Date:      2022-09-18 22:02:14.071895
Type:      <class 'ValueError'>
Message:   There is an error
Trace:     Traceback (most recent call last):
             File "C:\Users\emiol\PycharmProjects\pythonProject\src\task4.py", line 30, in wrapper
               func(*args, **kwargs)
             File "C:\Users\emiol\PycharmProjects\pythonProject\src\task1.py", line 33, in wrapper
               func(*args, **kwargs)
             File "C:\Users\emiol\PycharmProjects\pythonProject\src\main.py", line 95, in fun5
               raise ValueError("There is an error")
           ValueError: There is an error

Date:      2022-09-18 22:02:14.073846
Type:      <class 'ArithmeticError'>
Message:   There is an error
Trace:     Traceback (most recent call last):
             File "C:\Users\emiol\PycharmProjects\pythonProject\src\task4.py", line 30, in wrapper
               func(*args, **kwargs)
             File "C:\Users\emiol\PycharmProjects\pythonProject\src\task2.py", line 48, in wrapper
               func(*args, **kwargs)
             File "C:\Users\emiol\PycharmProjects\pythonProject\src\main.py", line 104, in fun6
               raise ArithmeticError("There is an error")
           ArithmeticError: There is an error

Date:      2022-09-18 22:02:14.073846
Type:      <class 'ZeroDivisionError'>
Message:   There is an error
Trace:     Traceback (most recent call last):
             File "C:\Users\emiol\PycharmProjects\pythonProject\src\task4.py", line 30, in wrapper
               func(*args, **kwargs)
             File "C:\Users\emiol\PycharmProjects\pythonProject\src\task3.py", line 47, in __call__
               self.func(*args, **kwargs)
             File "C:\Users\emiol\PycharmProjects\pythonProject\src\main.py", line 113, in fun7
               raise ZeroDivisionError("There is an error")
           ZeroDivisionError: There is an error

